Workbook

Sheet TUẦN 1
A1: TEAM A
A2: NGÀY THÁNG | B2: 46379 | C2: 46380 | D2: 46381 | E2: 46382 | F2: 46383 | G2: 46384 | I2: Tổng tuần
A4: Long Bùi | B4: 15.01 | C4: 16.52 | D4: 16.02 | E4: 15.12 | F4: 18.07 | G4: 7.21 | I4: =SUM(B4:H5) -> 87.95
A6: Văn Mạnh | B6: 10.01 | C6: 11.21 | D6: 12.12 | E6: 18.58 | F6: 0.27 | G6: 8.77 | I6: =SUM(B6:H7) -> 88.55
C7: 8.58 | D7: 7.16 | F7: 5.05 | G7: 6.8
A8: Ngô Thị Hòa | B8: 10.25 | C8: 15.02 | D8: 11.02 | E8: 11.41 | F8: 10.19 | G8: 0 | I8: =SUM(B8:H9) -> 67.04
D9: 2.86 | F9: 6.29
A10: Bích Bo | B10: 0 | C10: 9.46 | D10: 0 | E10: 12.21 | F10: 15.34 | G10: 0 | I10: =SUM(B10:H11) -> 37.01
A12: Quốc Cường | B12: 11 | C12: 0 | D12: 10.04 | E12: 11.09 | F12: 0 | G12: 16.03 | I12: =SUM(B12:H13) -> 48.16
A14: Tuyết Nga | B14: 8.08 | C14: 3.26 | D14: 8.43 | E14: 4.3 | F14: 0 | G14: 0 | I14: =SUM(B14:H15) -> 24.07
A16: Nguyễn Thủy | B16: 10.6 | C16: 6.86 | D16: 7.41 | E16: 8.33 | F16: 6.06 | G16: 6.52 | I16: =SUM(B16:H19) -> 63.29
F17: 9.17 | G17: 8.34
A20: Tổng ngày | B20: =SUM(B4:B19) -> 64.95 | C20: =SUM(C4:C19) -> 70.91 | D20: =SUM(D4:D19) -> 75.06 | E20: =SUM(E4:E19) -> 81.04 | F20: =SUM(F4:F19) -> 70.44 | G20: =SUM(G4:G19) -> 53.67 | H20: =SUM(H4:H19) -> 0
A21: Tổng Tuần | B21: =SUM(B20:H20) -> 416.07
A22: TỔNG THÁNG | B22: =B21 -> 416.07
A25: TEAM B
A26: NGÀY THÁNG | B26: 46379 | C26: 46380 | D26: 46381 | E26: 46382 | F26: 46383 | G26: 46384 | I26: Tổng tuần
A28: Danh Toại | B28: 15.08 | C28: 18.13 | D28: 20.41 | E28: 15.5 | F28: 22.13 | G28: 42.22 | I28: =SUM(B28:H29) -> 187.61
B29: 10.23 | C29: 12.14 | D29: 16.01 | E29: 15.76
A30: Thành Hưng | B30: 25.01 | C30: 10.26 | D30: 0 | E30: 0 | F30: 0 | G30: 0 | I30: =SUM(B30:H31) -> 35.27
A32: Khánh Ly | B32: 6.31 | C32: 8.45 | D32: 9.11 | E32: 10.76 | F32: 10.45 | G32: 0 | I32: =SUM(B32:H33) -> 45.08
A34: Thúy Bizfood | B34: 12.2 | C34: 12.24 | D34: 14.42 | E34: 15.51 | F34: 11.01 | G34: 23.32 | I34: =SUM(B34:H35) -> 88.7
A36: Đình Thành | B36: 11.03 | C36: 11.02 | D36: 12.03 | E36: 11.01 | F36: 0 | G36: 23.32 | I36: =SUM(B36:H37) -> 68.41
A38: Phùng Hồng | B38: 0 | C38: 0 | D38: 8.09 | E38: 10.01 | F38: 11.05 | G38: 10.65 | I38: =SUM(B38:H39) -> 47.92
G39: 8.12
A40: Khánh Beo | B40: 15.02 | C40: 7.36 | D40: 10.02 | E40: 10 | F40: 15.01 | G40: 0 | I40: =SUM(B40:H42) -> 57.41
A43: Tổng ngày | B43: =SUM(B28:B42) -> 94.88 | C43: =SUM(C28:C42) -> 79.6 | D43: =SUM(D28:D42) -> 90.09 | E43: =SUM(E28:E42) -> 88.55 | F43: =SUM(F28:F42) -> 69.65 | G43: =SUM(G28:G42) -> 107.63 | H43: =SUM(H28:H42) -> 0
A44: Tổng Tuần | B44: =SUM(B43:H43) -> 530.4
A45: TỔNG THÁNG | B45: =B44 -> 530.4
A48: TEAM C
A49: NGÀY THÁNG | B49: 46379 | C49: 46380 | D49: 46381 | E49: 46382 | F49: 46383 | G49: 46384 | I49: Tổng tuần
A51: Quang Phạm | B51: 15.15 | C51: 15.25 | D51: 16.3 | E51: 15.45 | F51: 15.02 | G51: 15.01 | I51: =SUM(B51:H52) -> 92.18
A53: Sơn - Ironman | B53: 10.11 | C53: 0 | D53: 21.12 | E53: 6.05 | F53: 21.98 | G53: 0 | I53: =SUM(B53:H54) -> 75.83
B54: 5.78 | C54: 0 | D54: 10.79
A55: Cường Cr | B55: 10.01 | C55: 21 | D55: 16 | E55: 0 | F55: 30 | G55: 0 | I55: =SUM(B55:H56) -> 77.01
A57: Quyetay | B57: 16.29 | C57: 0 | D57: 0 | E57: 8.05 | F57: 0 | G57: 22.95 | I57: =SUM(B57:H58) -> 47.29
A59: Trần Huy | B59: 15.02 | C59: 15.67 | D59: 0 | E59: 11.25 | F59: 12.44 | G59: 11.06 | I59: =SUM(B59:H60) -> 65.44
A61: Hiền Hồ | B61: 7.01 | C61: 7.21 | D61: 7.18 | E61: 7.28 | F61: 10.17 | G61: 22.88 | I61: =SUM(B61:H62) -> 84.37
B62: 5.01 | C62: 4.81 | E62: 5.52 | G62: 7.3
A63: Mạnh Khang | B63: 11.03 | C63: 5.37 | D63: 11.21 | E63: 3.42 | F63: 10.27 | G63: 11.69 | I63: =SUM(B63:H65) -> 64.04
...

Sheet TUẦN 2
A1: TEAM A
A2: NGÀY THÁNG | B2: 46385 | C2: 46386 | D2: 46387 | E2: 46023 | F2: 46024 | G2: 46025 | H2: 46026 | I2: Tổng tuần
A4: Long Bùi | B4: 21.02 | C4: 21.01 | D4: 11.01 | E4: 11.26 | F4: 14.11 | G4: 23.42 | H4: 21.01 | I4: =SUM(B4:H5) -> 122.84
A6: Văn Mạnh | B6: 10.28 | C6: 15 | D6: 5.02 | E6: 20.26 | F6: 0.81 | G6: 12.73 | H6: 20.29 | I6: =SUM(B6:H7) -> 106.97
C7: 11.46 | E7: 1.12 | F7: 10
A8: Ngô Thị Hòa | B8: 11.12 | C8: 6.38 | D8: 7.13 | E8: 12 | F8: 15.61 | G8: 12.05 | H8: 7.58 | I8: =SUM(B8:H9) -> 77.5
B9: 5.63
A10: Bích Bo | B10: 10.02 | C10: 11.02 | D10: 0 | E10: 20.26 | F10: 10.01 | G10: 11.04 | H10: 23.28 | I10: =SUM(B10:H11) -> 92.46
B11: 6.83
A12: Quốc Cường | B12: 0 | C12: 13.55 | D12: 0 | E12: 0 | F12: 15.23 | G12: 12.31 | H12: 12.24 | I12: =SUM(B12:H13) -> 53.33
A14: Tuyết Nga | B14: 4.25 | C14: 0 | D14: 0 | E14: 0 | F14: 6.33 | G14: 0 | H14: 0 | I14: =SUM(B14:H15) -> 10.58
A16: Nguyễn Thủy | B16: 2.233 | C16: 8.22 | D16: 10.48 | E16: 20.26 | F16: 6.07 | G16: 7.16 | H16: 10.45 | I16: =SUM(B16:H19) -> 107.72
B17: 11.91 | E17: 2.242 | F17: 8.49 | G17: 9.15 | H17: 1.603
F18: 0.822 | G18: 3.71 | H18: 4.92
A20: Tổng ngày | B20: =SUM(B4:B19) -> 83.293 | C20: =SUM(C4:C19) -> 86.64 | D20: =SUM(D4:D19) -> 33.64 | E20: =SUM(E4:E19) -> 87.402 | F20: =SUM(F4:F19) -> 87.482 | G20: =SUM(G4:G19) -> 91.57 | H20: =SUM(H4:H19) -> 101.373
A21: Tổng Tuần | B21: =SUM(B20:H20) -> 571.4
A22: TỔNG THÁNG | B22: =B21+'TUẦN 1'!B22:H22 -> 987.47
A25: TEAM B
A26: NGÀY THÁNG | B26: 46385 | C26: 46386 | D26: 46387 | E26: 46023 | F26: 46024 | G26: 46025 | H26: 46026 | I26: Tổng tuần
A28: Danh Toại | B28: 15.56 | C28: 16.03 | D28: 14.21 | E28: 20.26 | F28: 16.32 | G28: 16.31 | H28: 23.3 | I28: =SUM(B28:H29) -> 233.9
B29: 16.22 | C29: 19.4 | D29: 11.62 | E29: 17.36 | F29: 12.62 | G29: 12.16 | H29: 22.53
A30: Thành Hưng | B30: 0 | C30: 7.21 | D30: 6.68 | E30: 0 | F30: 0 | G30: 0 | H30: 0 | I30: =SUM(B30:H31) -> 13.89
A32: Khánh Ly | B32: 9.83 | C32: 4.68 | D32: 6.41 | E32: 14 | F32: 10.41 | G32: 7.72 | H32: 10.33 | I32: =SUM(B32:H33) -> 63.38
A34: Thúy Bizfood | B34: 18.02 | C34: 16.25 | D34: 18.08 | E34: 20.26 | F34: 9.18 | G34: 10.11 | H34: 16.04 | I34: =SUM(B34:H35) -> 147.74
F35: 10.33 | G35: 12.46 | H35: 17.01
A36: Đình Thành | B36: 10.05 | C36: 10.03 | D36: 10.13 | E36: 20.26 | F36: 14.05 | G36: 12.53 | H36: 19.44 | I36: =SUM(B36:H37) -> 154.38
B37: 10.1 | C37: 15.02 | D37: 10.3 | E37: 5.03 | F37: 7 | G37: 10.44
A38: Phùng Hồng | B38: 8.05 | C38: 13.03 | D38: 10.05 | E38: 6.02 | F38: 12.68 | G38: 11.65 | H38: 13.33 | I38: =SUM(B38:H39) -> 134.28
B39: 6.3 | D39: 11.56 | E39: 8.74 | F39: 6.05 | G39: 12.68 | H39: 14.14
A40: Khánh Beo | B40: 16.07 | C40: 15.56 | D40: 12.01 | E40: 20.26 | F40: 11.57 | G40: 0 | H40: 0 | I40: =SUM(B40:H42) -> 75.47
A43: Tổng ngày | B43: =SUM(B28:B42) -> 110.2 | C43: =SUM(C28:C42) -> 117.21 | D43: =SUM(D28:D42) -> 111.05 | E43: =SUM(E28:E42) -> 132.19 | F43: =SUM(F28:F42) -> 110.21 | G43: =SUM(G28:G42) -> 106.06 | H43: =SUM(H28:H42) -> 136.12
A44: Tổng Tuần | B44: =SUM(B43:H43) -> 823.04
A45: TỔNG THÁNG | B45: =B44+'TUẦN 1'!B45:H45 -> 1353.44
A48: TEAM C
A49: NGÀY THÁNG | B49: 46385 | C49: 46386 | D49: 46387 | E49: 46023 | F49: 46024 | G49: 46025 | H49: 46026 | I49: Tổng tuần
A51: Quang Phạm | B51: 15.01 | C51: 15.01 | D51: 15 | E51: 20.26 | F51: 12.52 | G51: 12.52 | H51: 16.76 | I51: =SUM(B51:H52) -> 107.08
A53: Sơn - Ironman | B53: 27.53 | C53: 23.03 | D53: 12.37 | E53: 20.26 | F53: 18.91 | G53: 0 | H53: 17.51 | I53: =SUM(B53:H54) -> 153.04
C54: 8.02 | D54: 8.58 | H54: 16.83
A55: Cường Cr | B55: 21 | C55: 0 | D55: 12 | E55: 20.26 | F55: 0 | G55: 0 | H55: 35 | I55: =SUM(B55:H56) -> 88.26
A57: Quyetay | B57: 6.5 | C57: 8.39 | D57: 0.73 | E57: 20.26 | F57: 4.61 | G57: 1.5 | H57: 0 | I57: =SUM(B57:H58) -> 41.99
...

Sheet TUẦN 3
A1: TEAM A
A2: NGÀY THÁNG | B2: 46027 | C2: 46028 | D2: 46029 | E2: 46030 | F2: 46031 | G2: 46032 | H2: 46033 | I2: Tổng tuần
A4: Long Bùi | B4: 15.36 | C4: 16.69 | D4: 16.21 | I4: =SUM(B4:H5) -> 48.26
A6: Văn Mạnh | B6: 15.25 | C6: 15.06 | D6: 18.31 | I6: =SUM(B6:H7) -> 54.68
C7: 6.06
A8: Ngô Thị Hòa | B8: 7.23 | C8: 11.1 | D8: 10.49 | I8: =SUM(B8:H9) -> 28.82
A10: Bích Bo | B10: 10 | C10: 8.15 | D10: 9.7 | I10: =SUM(B10:H11) -> 48.8
C11: 10.27 | D11: 10.68
A12: Quốc Cường | B12: 15.42 | C12: 0 | D12: 12.45 | I12: =SUM(B12:H13) -> 27.87
A14: Tuyết Nga | B14: 4.01 | C14: 0 | D14: 0 | I14: =SUM(B14:H15) -> 4.01
A16: Nguyễn Thủy | B16: 8.62 | C16: 10.23 | D16: 7.45 | I16: =SUM(B16:H19) -> 31.062
B17: 3.86 | D17: 0.551
D18: 0.351
A20: Tổng ngày | B20: =SUM(B4:B19) -> 79.75 | C20: =SUM(C4:C19) -> 77.56 | D20: =SUM(D4:D19) -> 86.192 | E20: =SUM(E4:E19) -> 0 | F20: =SUM(F4:F19) -> 0 | G20: =SUM(G4:G19) -> 0 | H20: =SUM(H4:H19) -> 0
A21: Tổng Tuần | B21: =SUM(B20:H20) -> 243.502
A22: TỔNG THÁNG | B22: =B840+'TUẦN 2'!B21:H21+'TUẦN 1'!B21:H21 -> 987.47
A25: TEAM B
A26: NGÀY THÁNG | B26: 46027 | C26: 46028 | D26: 46029 | E26: 46030 | F26: 46031 | G26: 46032 | H26: 46033 | I26: Tổng tuần
A28: Danh Toại | B28: 22.31 | C28: 16.29 | D28: 16.4 | I28: =SUM(B28:H29) -> 97.31
B29: 16.41 | C29: 11.59 | D29: 14.31
A30: Thành Hưng | B30: 9.5 | C30: 7.11 | D30: 12.62 | I30: =SUM(B30:H31) -> 29.23
A32: Khánh Ly | B32: 6.28 | C32: 6.05 | D32: 3.32 | I32: =SUM(B32:H33) -> 15.65
A34: Thúy Bizfood | B34: 7.03 | C34: 10.11 | D34: 8.38 | I34: =SUM(B34:H35) -> 70.32
B35: 15.2 | C35: 15.47 | D35: 14.13
A36: Đình Thành | B36: 10.12 | C36: 3.7 | D36: 15.03 | I36: =SUM(B36:H37) -> 83.83
B37: 12.44 | C37: 21.07 | D37: 21.47
A38: Phùng Hồng | B38: 14.45 | C38: 10.01 | D38: 11.06 | I38: =SUM(B38:H39) -> 75.49
B39: 10.01 | C39: 15.04 | D39: 14.92
A40: Khánh Beo | B40: 15.02 | C40: 15.51 | D40: 10.02 | I40: =SUM(B40:H42) -> 40.55
A43: Tổng ngày | B43: =SUM(B28:B42) -> 138.77 | C43: =SUM(C28:C42) -> 131.95 | D43: =SUM(D28:D42) -> 141.66 | E43: =SUM(E28:E42) -> 0 | F43: =SUM(F28:F42) -> 0 | G43: =SUM(G28:G42) -> 0 | H43: =SUM(H28:H42) -> 0
A44: Tổng Tuần | B44: =SUM(B43:H43) -> 412.38
A45: TỔNG THÁNG | B45: =B863+'TUẦN 2'!B44:H44+'TUẦN 1'!B44:H44 -> 1353.44
A48: TEAM C
A49: NGÀY THÁNG | B49: 46027 | C49: 46028 | D49: 46029 | E49: 46030 | F49: 46031 | G49: 46032 | H49: 46033 | I49: Tổng tuần
A51: Quang Phạm | B51: 0 | C51: 16.02 | D51: 15.05 | I51: =SUM(B51:H52) -> 31.07
A53: Sơn - Ironman | B53: 17.25 | C53: 18.09 | D53: 17.4 | I53: =SUM(B53:H54) -> 52.74
A55: Cường Cr | B55: 15 | C55: 21 | D55: 15 | I55: =SUM(B55:H56) -> 51
A57: Quyetay | B57: 4.6 | C57: 5.17 | D57: 8.57 | I57: =SUM(B57:H58) -> 19.56
C58: 1.22
A59: Trần Huy | B59: 15.3 | C59: 8.3 | I59: =SUM(B59:H60) -> 23.6
...

Sheet TUẦN 4
A1: TEAM A
A2: NGÀY THÁNG | B2: 46034 | C2: 46035 | D2: 46036 | E2: 46037 | F2: 46038 | G2: 46039 | H2: 46040 | I2: Tổng tuần
A4: Long Bùi | B4: 0 | C4: 0 | D4: 0 | E4: 0 | F4: 0 | G4: 0 | H4: 0 | I4: =SUM(B4:H5) -> 0
A6: Văn Mạnh | B6: 0 | C6: 0 | D6: 0 | E6: 0 | F6: 0 | G6: 0 | H6: 0 | I6: =SUM(B6:H7) -> 0
A8: Ngô Thị Hòa | B8: 0 | C8: 0 | D8: 0 | E8: 0 | F8: 0 | G8: 0 | H8: 0 | I8: =SUM(B8:H9) -> 0
A10: Bích Bo | B10: 0 | C10: 0 | D10: 0 | E10: 0 | F10: 0 | G10: 0 | H10: 0 | I10: =SUM(B10:H11) -> 0
A12: Quốc Cường | C12: 0 | D12: 0 | E12: 0 | F12: 0 | G12: 0 | H12: 0 | I12: =SUM(B12:H13) -> 0
A14: Tuyết Nga | B14: 0 | C14: 0 | D14: 0 | E14: 0 | F14: 0 | G14: 0 | H14: 0 | I14: =SUM(B14:H15) -> 0
A16: Nguyễn Thủy | B16: 0 | C16: 0 | D16: 0 | E16: 0 | F16: 0 | G16: 0 | H16: 0 | I16: =SUM(B16:H19) -> 0
A20: Tổng ngày | B20: =SUM(B4:B19) -> 0 | C20: =SUM(C4:C19) -> 0 | D20: =SUM(D4:D19) -> 0 | E20: =SUM(E4:E19) -> 0 | F20: =SUM(F4:F19) -> 0 | G20: =SUM(G4:G19) -> 0 | H20: =SUM(H4:H19) -> 0
A21: Tổng Tuần | B21: =SUM(B20:H20) -> 0
A22: TỔNG THÁNG | B22: =B21+'TUẦN 3'!B21:H21+'TUẦN 2'!B21:H21+'TUẦN 1'!B21:H21 -> 1230.972
A25: TEAM B
A26: NGÀY THÁNG | B26: 46385 | C26: 46386 | D26: 46387 | E26: 46023 | F26: 46024 | G26: 46025 | H26: 46026 | I26: Tổng tuần
A28: Danh Toại | I28: =SUM(B28:H29) -> 0
A30: Thành Hưng | I30: =SUM(B30:H31) -> 0
A32: Khánh Ly | I32: =SUM(B32:H33) -> 0
A34: Thúy Bizfood | I34: =SUM(B34:H35) -> 0
A36: Đình Thành | I36: =SUM(B36:H37) -> 0
A38: Phùng Hồng | I38: =SUM(B38:H39) -> 0
A40: Khánh Beo | I40: =SUM(B40:H42) -> 0
A43: Tổng ngày | B43: =SUM(B28:B42) -> 0 | C43: =SUM(C28:C42) -> 0 | D43: =SUM(D28:D42) -> 0 | E43: =SUM(E28:E42) -> 0 | F43: =SUM(F28:F42) -> 0 | G43: =SUM(G28:G42) -> 0 | H43: =SUM(H28:H42) -> 0
A44: Tổng Tuần | B44: =SUM(B43:H43) -> 0
A45: TỔNG THÁNG | B45: =B44+'TUẦN 3'!B44:H44+'TUẦN 2'!B44:H44+'TUẦN 1'!B44:H44 -> 1765.82
A48: TEAM C
A49: NGÀY THÁNG | B49: 46385 | C49: 46386 | D49: 46387 | E49: 46023 | F49: 46024 | G49: 46025 | H49: 46026 | I49: Tổng tuần
A51: Quang Phạm | I51: =SUM(B51:H52) -> 0
A53: Sơn - Ironman | I53: =SUM(B53:H54) -> 0
A55: Cường Cr | I55: =SUM(B55:H56) -> 0
A57: Quyetay | I57: =SUM(B57:H58) -> 0
A59: Trần Huy | I59: =SUM(B59:H60) -> 0
A61: Hiền Hồ | I61: =SUM(B61:H62) -> 0
A63: Mạnh Khang | I63: =SUM(B63:H65) -> 0
A66: Tổng ngày | B66: =SUM(B51:B65) -> 0 | C66: =SUM(C51:C65) -> 0 | D66: =SUM(D51:D65) -> 0 | E66: =SUM(E51:E65) -> 0 | F66: =SUM(F51:F65) -> 0 | G66: =SUM(G51:G65) -> 0 | H66: =SUM(H51:H65) -> 0
A67: Tổng Tuần | B67: =SUM(B66:H66) -> 0
A68: TỔNG THÁNG | B68: =B67+'TUẦN 3'!B67:H67+'TUẦN 2'!B67:H67+'TUẦN 1'!B67:H67 -> 1413.11
A71: TEAM D
A72: NGÀY THÁNG | B72: 46385 | C72: 46386 | D72: 46387 | E72: 46023 | F72: 46024 | G72: 46025 | H72: 46026 | I72: Tổng tuần
A74: Thành Phi | F74: 150 | I74: =SUM(B74:H75) -> 150
A76: Tuấn Nổ | I76: =SUM(B76:H77) -> 0
...
